---
title: '16、Promise'
categories: 日常总结
tags:
 - js
 - es6
collapsable: true
---

### 概念
::: tip
Promise 是异步编程的一种解决方案，是一个容器对象，里面保存着某个未来才会知道结果的事件（通常是一个异步操作），并且提供统一的API处理此事件。
:::

### 两个特点
#### 1、对象的状态不受外界影响
Promise 代表一个异步操作，有三种状态：<font color='red'>pending</font>（进行中）、<font color='red'>fulfilled</font> （已成功 resolved）、<font color='red'>rejected</font>（已失败），只有异步操作的结果，可以决定当前是哪一种状态，任何其他操作都无法改变这个状态。
#### 2、一旦状态改变，就不会在变，任何时候都可以得到这个结果。
Promise 的状态改变，只有两种可能：从 <font color='red'>pending</font> 变为 <font color='red'>fulfilled</font> 和从 <font color='red'>pending</font> 变为 <font color='red'>rejected</font>，只要这两种情况发生，状态就固定了
::: warning 注意：
<font color='red'>resolved</font> 统一只指 <font color='red'>fulfilled</font> 状态，经过<font color='red'> catch() </font>方法处理后状态是成功的（resolved）
:::

### 三个缺点
1、一旦创建，无法取消Promise

2、如果不设置回调函数，Promise 内部抛出的错误不会反映到外部

3、当处于 pending 状态时，无法得知目前进展的哪一个阶段

### 基本用法
Promise对象是一个构造函数，用来生成 Promise 实例，之后可以用then方法分别指定 resolved 状态和 rejected（可选） 状态的回调函数。
```js
const promise = new Promise(function(resolve, reject) => {
    if(/* 异步操作成功 */) {
        resolve(value)
    } else {
        reject(erro)
    }
})
// rejected回调函数是可选的
promise.then(function() {
    // 成功 resolved状态的回调函数
}, function() {
    // 失败 rejected状态的回调函数
})
```
::: tip 参数
<font color='red'>resolve</font> 和 <font color='red'>reject</font>。它们是两个函数，由 JavaScript 引擎提供，不用自己部署

<font color='red'>resolve</font>：将 Promise 状态从 pedning（未完成）变为 resolved（成功），在异步操作成功后调用，并将异步结果作为参数传递出去

<font color='red'>reject</font>：将 Promise 状态从 pending （未完成）变为 rejected （失败），将错误信心当作参数传递出去
:::

- Promise 新建后就会立即执行，then方法指定的回调函数，将在当前脚本所有同步任务执行完才会执行
```js
let promise = new Promise((resolve, reject) => {
    resolve(2)
    console.log(1)
})
promise.then((val) => {
    console.log(val)
})
console.log(3)

// 输出结果顺序 ：1  3  2
```

- - 一般来说，调用resolve或reject以后，Promise 的使命就完成了，后继操作应该放到then方法里面，而不应该直接写在resolve或reject的后面。所以，最好在它们前面加上 <font color='red'>return</font> 语句，这样就不会有意外。
```js
let promise = new Promise((resolve, reject) => {
    return resolve(2)
    console.log('1') // 不再执行
})
```

### then()
- then 方法是定义在原型对象 Promise.prototype 上的，第一个参数是resolved状态的回调函数，第二个参数（可选）是rejected状态的回调函数。
- then 方法返回的是一个新的Promise对象，所以then方法可以进行链式调用
```js
new Promise((resolve, reject) => {
    setTimeout(() => {
        return resolve(1)
    }, 1000)
}).then((val) => {
    console.log(val)    // 1
    // return new Promise((resolve, reject) => {
    //     setTimeout(() => {
    //         resolve(2)
    //     }, 1000)
    // })
    return 2
}).then((val) => {
    console.log(val)    // 2
    return 3
}).then( val => {
    console.log(val)    // 3
})
```
- then 嵌套情况
```js
new Promise((resolve, reject) => {
    setTimeout(() => {
        return resolve(1)
    }, 1000)
}).then((val) => {
    return new Promise((resolve, reject) => {
        console.log(val)    // 1
        setTimeout(() => {
            resolve(2)
        }, 1000)
    }).then((val) => {
        console.log(val)    // 2
        return 3
    }).then((val) => {
        console.log(val)    // 3
        return 3
    })
})
// 等同于 （展开）
new Promise((resolve, reject) => {
    setTimeout(() => {
        return resolve(1)
    }, 1000)
}).then((val) => {
    console.log(val)    // 1
    return new Promise((resolve, reject) => {
        setTimeout(() => {
            resolve(2)
        }, 1000)
    })
}).then((val) => {
    console.log(val)    // 2
    return 3
}).then((val) => {
    console.log(val)    // 3
})
```

### catch()
- 用于指定发生错误时的回调函数，是 <font color='red'> .then(null, reject) </font> 或 <font color='red'> .then(undefined, reject) </font>的别名
```js
p.then((val) => console.log('fulfilled:', val))
    .catch((err) => console.log('rejected', err));

// 等同于
p.then((val) => console.log('fulfilled:', val))
    .then(null, (err) => console.log("rejected:", err));
```
- throw new Error 会被catch捕获
```js
const promise = new Promise(function(resolve, reject) {
    throw new Error('test');
});
promise.catch(function(error) {
    console.log(error);
});
// Error: test
```

- reject()方法的作用，等同于抛出错误
```js
const promise = new Promise(function(resolve, reject) {
    reject('Error');
});
promise.catch(function(error) {
    console.log(error);     // Error
});
```

-  Promise 状态已经变成resolved，再抛出错误是无效的
```js
const promise = new Promise(function(resolve, reject) {
    resolve(123)
    throw new Error('test'); // 或者 reject('Error')都是无效的
    
});
promise.catch(function(error) {
    console.log(error);     // Error
});
```

- Promise 对象的错误具有“冒泡”性质，会一直向后传递，直到被捕获为止。一旦发现reject()或破除错误后，后面的语句不再执行，直接执行catch方法
```js
new Promise((resolve, reject) => {
    throw new Error('Error1')
    resolve(111);   // 不会被执行
}).then((val) => { // 不会被执行
    console.log(val)
    return new Promise((resolve, reject) => {
        resolve('success');
    });
}).then((val) => { // 不会被执行
    console.log(val)
}).catch(function(error) {
    // 处理前面三个Promise产生的错误
    console.log(error)
});
```
- 一般来说，不要在then()方法里面定义 reject 状态的回调函数（即then的第二个参数），最好使用catch方法处理
```js
// 不推荐写法
promise.then(function(data) {
    // success
}, function(err) {
    // error
});

// 推荐写法
promise.then(function(data) {
    // success
})
.catch(function(err) {
    // error
});
```
::: warning 注意：
跟传统的try/catch代码块不同的是，如果没有使用catch()方法指定错误处理的回调函数，Promise 对象抛出的错误不会传递到外层代码，即不会有任何反应。
不会影响外部代码，通俗的说法就是“Promise 会吃掉错误”。
:::

- 建议Promise 对象后要跟 catch() 方法，来处理当前Promise的抛出错误，catch() 方法还是返回Promise对象，因此后面可以接着调用 then() 方法
```js
Promise.resolve()
.catch((error) => { // 如果没有报错，则会跳过此catch
    console.log('oh no', error);
})
.then(() => {
    console.log('carry on');
}).catch((error) => {
    console.log('oh no', error);
})
```

### finally()
- 不管Promise对象最后状态如何，都会执行此方法，没有参数，本质上是then方法的特例。
```js
promise
.finally(() => {
    // 语句
});

// 等同于
promise
.then(
    result => {
        // 语句
        return result;
    },
    error => {
        // 语句
        throw error;
    }
);
```

### Promise.all()
- 将多个 Promise 实例包装成一个新的 Promise 实例
```js
const p = Promise.all([p1, p2, p3]);
```
- p 的状态由p1、p2、p3决定，分两种情况：

1、只有状态都变成 resolved ，p 的状态才变成 resolved，此时p1、p2、p3的返回值组成一个数组，传递给 p 的回调函数

2、只要其中一个被 rejected ，p 的状态就变成 rejected，此时第一个被 reject 实例的返回值，传递给 p 的回调函数
```js
const p1 = new Promise((resolve, reject) => {
    return resolve(111);
}).then((val) => {
    return val
})

const p2 = new Promise((resolve, reject) => {
    return resolve(222);
}).then((val) => {
    return val
})

Promise.all([p1, p2]).then((val) => {
    console.log(val)    // [111, 222]
})

/*------------------------抛出错误例子如下------------------------*/

const p3 = new Promise((resolve, reject) => {
    throw new Error('p3抛出错误')
}).then((val) => {
    return val
})

const p4 = new Promise((resolve, reject) => {
    return reject('p4抛出错误');
}).then((val) => {
    return val
})

Promise.all([p3, p4]).then((val) => {
    console.log(val)    // Error: p3抛出错误
})
```
::: warning
<font color='red'>注意：</font>如果参数promise对象中，有自己的catch方法，那么抛出的错误不会走到all()方法的catch()方法中，只要其中一个没有定义 catch() 方法，抛出错误后就会走all() 方法的 catch()
:::
```js
const p1 = new Promise((resolve, reject) => {
    return reject('p1抛出错误');
}).then((val) => {
    return val
}).catch((erro) => {
    console.log(erro)   // p1抛出错误
    return erro
})

const p2 = new Promise((resolve, reject) => {
    return resolve(222);
}).then((val) => {
    return val
})

Promise.all([p1, p2]).then((val) => {
    console.log(val)    //  ["p1抛出错误", 222]
}).catch((erro) => {
    console.log(erro)   // 不执行catch
})

/*------------------------有一个没有定义catch并且抛出错误------------------------*/

const p3 = new Promise((resolve, reject) => {
    return reject('p3抛出错误');
}).then((val) => {
    return val
}).catch((erro) => {
    console.log(erro)   // p3抛出错误
    return erro
})

const p4 = new Promise((resolve, reject) => {
    return reject('p4抛出错误');
}).then((val) => {
    return val
})

Promise.all([p3, p4]).then((val) => {
    console.log(val)    //  不执行
}).catch((erro) => {
    console.log(erro)   // p4抛出错误
})
```

### Promise.race()
- 于all()方法相同，将多个Promise 实例，包装成一个Promise 实例，不同的是race() 方法会检测率先改变状态的promise 实例，将返回值作为参数传递下去
```js
const p1 = new Promise((resolve, reject) => {
    setTimeout(() => {
        return resolve(222);
    }, 1000)
}).then((val) => {
    return val
})

const p2 = new Promise((resolve, reject) => {
    return resolve(333);
}).then((val) => {
    return val
})

Promise.race([p1, p2]).then((val) => {
    console.log(val)    //  [333]
}).catch((erro) => {
    console.log(erro)   // 不执行catch
})

/*------------------------有then有catch的情况 resolve()执行比reject()快，只有其中之一不影响------------------------*/

const p3 = new Promise((resolve, reject) => {
    return reject('有then有catch，状态改变慢');
}).catch((erro) => {
    return erro
}).then((val) => {      // 如果将此then()方法去除，会打印上面的结果
    return val
})

const p4 = new Promise((resolve, reject) => {
    return resolve(666);
}).then((val) => {
    return val
})

Promise.race([p3, p4]).then((val) => {
    console.log(val)    //  [666]
}).catch((erro) => {
    console.log(erro)   // 不执行catch
})
```

### Promise.allSettled()
- 将多个Promise 实例，包装成一个Promise 实例，只有等到所有这些参数实例都返回结果，不管是 resolved 还是 rejected，包装实例才会结束，调用then()方法（无catch()）将返回结果以数组的形式传递，每个成员是一个对象，包含 status 属性和 value 属性

| 属性名 | 属性值 |
| :--- | :--- |
| status | promise最终状态 fulfilled / rejected |
| value | promise的返回值 |
```js
const p1 = new Promise((resolve, reject) => {
    return reject('p1抛出错误');
}).then((val) => {
    return val
})

const p2 = new Promise((resolve, reject) => {
    return resolve(333);
}).then((val) => {
    return val
})

Promise.allSettled([p1, p2]).then((val) => {
    console.log(val)
    //  [{status: "rejected", reason: "p1抛出错误"},{status: "fulfilled", value: 333}]
})

- 有时候，我们不关心异步操作的结果，只关心这些操作有没有结束。这时，Promise.allSettled()方法就很有用
```

### Promise.any()
-  将多个Promise 实例，包装成一个Promise 实例，只要参数实例有一个变成<font color='red'> fulfilled </font>状态，包装实例就会变成<font color='red'> fulfilled </font>状态，如果所有参数实例都变成<font color='red'> rejected </font>状态，包装实例才会变成 <font color='red'> rejected </font>状态
::: warning 注意
Promise.any() 方法依然是实验性的，尚未被所有的浏览器完全支持。它当前处于 TC39 第三阶段草案（Stage 3）
:::
```js
const p1 = new Promise((resolve, reject) => {
    return reject('p1抛出错误');
}).then((val) => {
    return val
})

const p2 = new Promise((resolve, reject) => {
    return resolve(222);
}).then((val) => {
    return val
})

Promise.any([p1, p2]).then((val) => {
    console.log(val)
})
```

### Promise.resolve()
- 将对象转为 Promise 对象
Promise.resolve()等价于下面的写法
```js
Promise.resolve('foo').then(val => {
    console.log(val)    // foo
})
// 等价于
new Promise(resolve => resolve('foo')).then(val => {
    console.log(val)    // foo
})
```
#### 参数具有四种情况
- (1)、参数是一个 Promise 实例，会原封不动的返回
- (2)、参数是一个 thenable 对象，对象具有then方法，立即执行 then 方法
```js
let thenable = {
    then: function(resolve, reject) {
        resolve(111)
    }
}

let p = Promise.resolve(thenable)
p.then((val) => {
    console.log(val)    // 111
})
// thenable对象的then方法执行后，对象p1的状态就变为resolved，从而立即执行最后那个then方法指定的回调函数，输出 111。
```
- (3)、参数不是对象，返回一个新的Promise，状态为 resolve
```js
const p = Promise.resolve('Hello');
// 等同于
// const p = new Promise(resolve => resolve('Hello'))

p.then(function (s){
    console.log(s)  // Hello
});
// Hello
```
- (4)、无参数，返回一个 resolve 状态的 Promise 对象
```js
const p = Promise.resolve();

p.then(function () {
    // ...
});
```

### Promise.reject()
返回一个 rejected 状态的 Promise 实例，参数作为后续方法的参数
```js
const p = Promise.reject('报错')
// 等同于
const p = new Promise((resolve, reject) => reject('报错'))

p.then(null,(val) => {
    console.log(val)    // 报错
})
// 等同于
p.catch(val => {
    console.log(val)    // 报错
})
```

下面代码中，Promise.reject方法的参数是一个thenable对象，执行以后，后面catch方法的参数不是reject抛出的“出错了”这个字符串，而是thenable对象。
```js
const thenable = {
    then(resolve, reject) {
        reject('出错了');
    }
};

Promise.reject(thenable).catch(val => {
    console.log(val === thenable)       // true
})
```

### 应用于加载图片
```js
const preloadImage = function(path) {
    return new Promise((resolve, reject) => {
        const image = new Image()
        image.onload = () => {
            return resolve('加载成功')
        }
        image.onerror = () => {
            return reject('加载失败')
        }
        image.src = path
    }).catch(erro => {
        console.log(erro)
    }).then((success) => {
        console.log(success)
    })
}
const path = 'https://www.wecode123.com/imgs/sassImg/company.png'
preloadImage(path)
```
